============================= test session starts ==============================
platform linux -- Python 3.9.2, pytest-6.2.2, py-1.10.0, pluggy-0.13.1
rootdir: /home/stidsem4/iut/2021/controle/chloe.landais/c16_03
collected 7 items

test_16_03.py .....F.                                                    [100%]

=================================== FAILURES ===================================
_____________________________ Test1603sute.test_8 ______________________________

self = <c16_03.test_16_03.Test1603sute testMethod=test_8>

    def test_8(self):
        try:
            from .main import Note
        except ImportError:
            assert False, "import de Note impossible"
        try:
>           from .main  import moyenne_Notes as mnotes
E           ImportError: cannot import name 'moyenne_Notes' from 'c16_03.main' (/home/stidsem4/iut/2021/controle/chloe.landais/c16_03/main.py)

test_16_03.py:71: ImportError

During handling of the above exception, another exception occurred:

self = <c16_03.test_16_03.Test1603sute testMethod=test_8>

    def test_8(self):
        try:
            from .main import Note
        except ImportError:
            assert False, "import de Note impossible"
        try:
            from .main  import moyenne_Notes as mnotes
        except ImportError:
            try:
>               from .main  import moyenne_notes as mnotes
E               ImportError: cannot import name 'moyenne_notes' from 'c16_03.main' (/home/stidsem4/iut/2021/controle/chloe.landais/c16_03/main.py)

test_16_03.py:74: ImportError

During handling of the above exception, another exception occurred:

self = <c16_03.test_16_03.Test1603sute testMethod=test_8>

    def test_8(self):
        try:
            from .main import Note
        except ImportError:
            assert False, "import de Note impossible"
        try:
            from .main  import moyenne_Notes as mnotes
        except ImportError:
            try:
                from .main  import moyenne_notes as mnotes
            except ImportError:
>               assert False, "La fonction moyenne_notes n'est pas définie"
E               AssertionError: La fonction moyenne_notes n'est pas définie
E               assert False

test_16_03.py:76: AssertionError
=========================== short test summary info ============================
FAILED test_16_03.py::Test1603sute::test_8 - AssertionError: La fonction moye...
========================= 1 failed, 6 passed in 0.10s ==========================
